Workbook

Sheet DRI Cost
E2: EZDK DRI Cost / Ton | G2: ERM DRI Cost / Ton
E4: Base | G4: Base
C6: Exchange Rate | D6: EGP/USD | E6: =+DRI!E6 -> 16.2 | G6: =+DRI!E6 -> 16.2
C8: DRI
C10: Total DRi Production Capacity | D10: Tons | E10: 3000000 | G10: 1900000
C11: Capacity Utilization | D11: % | E11: 1 | G11: 1
C13: DRI Selling Price | D13: LE | E13: 6465.4133 | G13: 6465.4133
C15: MRMR | D15: Ratio | E15: =+DRI!E11 -> 1.5 | G15: =+DRI!F11 -> 1.43
C16: Production | D16: Tons | E16: ='EZDK Rebar'!E26+'EZDK Flat'!E26 -> 232533.39 | G16: ='EFS Rebar'!E26+'ESR Rebar'!E28 -> 86694.469
C17: Rquired IOP | D17: Tons | E17: =E16*E15 -> 348800.08 | G17: =G16*G15 -> 123973.09
C19: Consumption
C20: Electricity | D20: Kwh/ton | E20: 41.587557 | G20: 27.124498
C21: Natural Gas | D21: Nm3/ton | E21: =+DRI!E12 -> 292.58 | G21: =+DRI!F12 -> 333
C22: N.Gas | D22: MMBTU/ton | E22: =E21/28 -> 10.449286 | G22: =G21/28 -> 11.892857
C23: Oxygen | D23: Nm3/ton | E23: 14.353732 | G23: 14.353732
C24: Nitrogen | D24: Nm3/ton | E24: 23.733239 | G24: 15.479443
C25: Water | D25: Nm3/ton | E25: 1.1750577 | G25: 1.1750577
C26: Chemicals | D26: ton/ton | E26: 1 | G26: 0.65222629
C27: Spare Parts & Maint | D27: ton/ton | E27: 0 | G27: 0
C28: External Services | D28: ton/ton | E28: 1 | G28: 0.61145318
C29: Other | D29: ton/ton | E29: 1 | G29: 1
C31: Unit Price
C32: Oxide Pellets
C33: IOP Landed Cost | D33: USD/ton | E33: =+DRI!E8 -> 130 | G33: =+DRI!F8 -> 136.62
C34: IOP Landed Cost | D34: EGP/ton | E34: =(E33*E6) -> 2106 | G34: =(G33*G6) -> 2213.244
C35: Electricity | D35: EGP/KWH | E35: 0.90462765 | G35: 0.90462765
C36: Natural Gas | D36: EGP/Nm3 | E36: =+E37*E6/28 -> 3.1821429 | G36: =+G37*G6/28 -> 3.1821429
C37: Natural Gas | D37: USD/MMBTU | E37: =+DRI!E9 -> 5.5 | G37: =+DRI!F9 -> 5.5
C38: Oxygen | D38: EGP/Nm3 | E38: 0.00017117713 | G38: 0.00017117713
C39: Nitrogen | D39: EGP/Nm3 | E39: 0.6568664 | G39: 0.6568664
C40: Water | D40: EGP/Nm3 | E40: 3.9785731 | G40: 3.8890995
C41: Chemicals | D41: LE/ton | E41: 24.778635 | G41: 24.778635
C42: Spare Parts & Maint | D42: LE/ton | E42: 0 | G42: 0
C43: External Services | D43: LE/ton | E43: 42.724299 | G43: 39
C44: Other | D44: LE/ton | E44: 35.802217 | G44: 0
C46: DRI Fixed Exp
C47: Labor Exp | D47: LE | E47: 54011352 | G47: 54011352
C48: DRI Dep | E48: 2.3974642e+08 | G48: 2.3974642e+08
C49: Other Exp (Exluding Dep) | D49: LE | E49: =347999806.05-239746417.14-E47 -> 54242037 | G49: =347999806.05-239746417.14-G47 -> 54242037
C51: Cost Per Ton
...

Sheet EZDK Rebar
E2: ='[1]EFS MS Flat'!N2 -> Base
C3: Steel Making - Stage #1
C5: FX Rate | E5: =+Billet!D7 -> 16.2
C6: Inflation
C8: Rebar Production Cap | E8: 2200000
C9: Rebar Production Cap Utlization | D9: % | E9: =E10/E8 -> 0.045454545
C10: MS Rebars Produced / Sold | E10: ='Market Share'!E6*1000 -> 100000
C12: Rebar Export Sales % | D12: % | E12: 0
C13: Rebar Local Sales % | D13: % | E13: 1
C15: Rebar Export Selling Price | D15: USD | E15: 0
C16: Rebar Local Selling Price | D16: USD | E16: 0
C17: Rebar Local Selling Price | D17: LE | E17: ='Market Share'!E29 -> 9300
C19: Produced Molten Steel | D19: Tons | E19: =E106 -> 159025 | G19: =E19*(E73+E74) -> 11221626
C20: Yeild Rate | D20: % | E20: =+Billet!E17% -> 0.8493
C21: Solid Charge | D21: Tons | E21: =E19/E20 -> 187242.43 | G21: =G19/E104 -> 71.005405 | H21: =G19/E156 -> 112.21626 | I21: =G19/G105 -> 75.537665
C23: Consumption
C24: Imported Scrap | D24: =+Billet!E15% -> 0.15977 | E24: =D24*$E$21 -> 29915.723
C25: Local Scrap | D25: =+Billet!E14% -> 0.04 | E25: =D25*$E$21 -> 7489.6973
C26: DRI | D26: =+Billet!E13% -> 0.8 | E26: =D26*$E$21 -> 149793.95
C27: Home scrap | D27: 0 | E27: =D27*$E$21 -> 0
C28: PIG IRON | D28: 0 | E28: =D28*$E$21 -> 0
C30: Byproduct (scrap) | D30: -0.031038676 | E30: =+D30*E21 -> -5811.7572
C32: Auxiliary Materials | D32: KG/ton | E32: 422.60159
C33: Refractories | D33: KG/ton | E33: 10.508598
C34: Electrodes | D34: KG/ton | E34: 2.5805617
C35: Other Fillers | D35: KG/ton | E35: 1.2842586
C37: Electricity (EAF & LF) | D37: KWH/Ton | E37: =+Billet!E20 -> 713.63
C38: Electricity (Aux - Airliq - Lime ) | D38: KWH/Ton | E38: 239.71539
C39: Natural Gas | D39: Nm3/ton | E39: 14.593054
C40: Water | D40: M3/ton | E40: 1.548884
C41: Oxygen | D41: Nm3/ton | E41: 34.797488
C42: Nitrogen | D42: Nm3/ton | E42: 4.0864981
C43: Aragon | D43: Nm3/ton | E43: 0.30455884
C45: Handling Machine over max. Qty. | D45: KG/ton | E45: 0.98684612
C46: Cutting LTS | D46: KG/ton | E46: 0
C48: Unit Purchase Price
C49: Imported Scrap | D49: $/ton | E49: =+Billet!E10 -> 300
C50: Local Scrap | D50: $/ton | E50: =+Billet!E9 -> 300
C51: DRI | D51: $/ton | E51: =+Billet!E8 -> 262.42129
C52: Home scrap | D52: $/ton | E52: 0
...

Sheet EFS Rebar
C3: Steel Making - Stage #1
C5: FX Rate | E5: =+Billet!D7 -> 16.2
C6: Inflation
C8: Rebar Production Cap | E8: 1200000
C9: Rebar Production Cap Utlization | D9: % | E9: =E10/E8 -> 0.058333333
C10: MS Rebars Produced / Sold | E10: ='Market Share'!E7*1000 -> 70000
C12: Rebar Export Sales % | D12: % | E12: 0
C13: Rebar Local Sales % | D13: % | E13: 1
C15: Rebar Export Selling Price | D15: USD | E15: 0
C16: Rebar Local Selling Price | D16: USD | E16: 0
C17: Rebar Local Selling Price | D17: LE | E17: ='Market Share'!E30 -> 9300
C19: Produced Molten Steel | D19: Tons | E19: =E106 -> 73531.926
C20: Yeild Rate | D20: % | E20: =+Billet!F17% -> 0.8417
C21: Solid Charge | D21: Tons | E21: =E19/E20 -> 87361.205
C23: Consumption
C24: Imported Scrap | D24: =+Billet!F15% -> 0.05978 | E24: =D24*$E$21 -> 5222.4528
C25: Local Scrap | D25: =+Billet!F14% -> 0.14 | E25: =D25*$E$21 -> 12230.569
C26: DRI | D26: =+Billet!F13% -> 0.8 | E26: =D26*$E$21 -> 69888.964
C27: Home scrap | D27: 0 | E27: =D27*$E$21 -> 0
C28: PIG IRON | D28: 0 | E28: =D28*$E$21 -> 0
C30: Byproduct (scrap) | D30: -0.034560194 | E30: =+D30*E21 -> -3019.2201
C32: Auxiliary Materials | D32: KG/ton | E32: 422.60159
C33: Refractories | D33: KG/ton | E33: 10.508598
C34: Electrodes | D34: KG/ton | E34: 2.5805617
C35: Other Fillers | D35: KG/ton | E35: 1.2842586
C37: Electricity (EAF & LF) | D37: KWH/Ton | E37: =+Billet!F20 -> 708.39 | G37: =+E37*E19 -> 52089281
C38: Electricity (Aux - Airliq - Lime ) | D38: KWH/Ton | E38: 239.71539 | G38: =+E38*E19 -> 17626734
C39: Natural Gas | D39: Nm3/ton | E39: 14.593054
C40: Water | D40: M3/ton | E40: 1.548884
C41: Oxygen | D41: Nm3/ton | E41: 34.797488
C42: Nitrogen | D42: Nm3/ton | E42: 4.0864981
C43: Aragon | D43: Nm3/ton | E43: 0.30455884
C45: Handling Machine over max. Qty. | D45: KG/ton | E45: 0.98684612
C46: Cutting LTS | D46: KG/ton | E46: 0
C48: Unit Purchase Price
C49: Imported Scrap | D49: $/ton | E49: =+Billet!F10 -> 267.27
C50: Local Scrap | D50: $/ton | E50: =+Billet!F9 -> 248.87
C51: DRI | D51: $/ton | E51: =+Billet!F8 -> 267.30003
C52: Home scrap | D52: $/ton | E52: 0
C53: PIG IRON | D53: $/ton | E53: 0
...

Sheet ERM Rolling
E2: Rebar Cost / Ton
E4: Base
C6: Exchange Rate | D6: EGP/USD | E6: =+Billet!D7 -> 16.2
C7: Inflation Rate | D7: % | E7: 0
C9: Rebars
C11: Total Rebar Production Capacity | D11: Tons | E11: 500000
C12: Capacity Utilization | D12: % | E12: 0.16079018
C13: Export Sales | D13: % | E13: =1-E14 -> 0
C14: Local Sales | D14: % | E14: 1
C16: Rebar Export Selling Price | D16: USD | E16: 0
C17: Rebar Local Selling Price | D17: LE | E17: 10743.186
C19: Rebars Yield | D19: % | E19: =+Rebar!G6% -> 0.97917872
C20: Rebar Production | D20: Tons | E20: =+'Market Share'!E8*1000 -> 30000
C21: Required Billets | D21: Tons | E21: =E20/E19 -> 30637.921
C23: Consumption
C24: Imported Billets Tons | D24: 0 | E24: =+D24*E21 -> 0
C25: Produced Billets Tons | D25: 1 | E25: =+D25*E21 -> 30637.921
C26: Local Billets Tons | D26: 0 | E26: =+D26*E21 -> 0
C27: By-product | D27: -0.011671911 | E27: =+D27*(E26+E25+E24) -> -357.60309
C28: Electricity | D28: Kwh/ton | E28: 106.2063
C29: Natural Gas | D29: Nm3/ton | E29: 27.662825
C30: N.Gas | D30: MMBTU/ton | E30: =E29/28 -> 0.98795802
C31: Recycled Water | D31: Nm3/ton | E31: 0.83725281
C32: Tying | D32: Kg/ton | E32: 1.6792739
C33: Chemicals | D33: Kg/ton | E33: 0.6430821
C34: Label & Rings | D34: Kg/ton | E34: 0.6430821
C35: Sp. Parts/Oil & Grease | D35: Kg/ton | E35: 0
C36: External Services | D36: Kg/ton | E36: 1
C38: Unit Price
C39: Imported Billets Purchase Price | D39: USD/ton | E39: 0
C40: Extra Cost | D40: LE/ton | E40: 0
C41: Landed Cost | D41: LE Eq/ton | E41: =(E6*E39)+E40 -> 0
C42: Good / Prod Billet Purchase Price | D42: LE/ton | E42: =+Rebar!G12*E6 -> 7110.1767
C43: Local Billet Purchase Price | D43: LE/ton | E43: 0
C44: By Product Reduction | D44: LE/ton | E44: =+E42 -> 7110.1767
C45: Electricity | D45: LE/KWH | E45: =0.07*E6 -> 1.134
C46: Natural Gas | D46: USD/MMBTU | E46: =+E47*28/E6 -> 7.3997061
C47: Natural Gas | D47: LE/NM3 | E47: 4.2812585
C48: Recycled Water | D48: LE/NM3 | E48: 13.174888
C49: Tying | D49: LE/Kg | E49: =11249.0074074074/1000 -> 11.249007
...

Sheet ESR Rebar
E2: ='[1]EFS MS Flat'!N2 -> Base
C3: Steel Making - Stage #1
C5: FX Rate | E5: =+Billet!D7 -> 16.2
C6: Inflation
C8: Rebar Production Cap | E8: 1200000
C9: Rebar Production Cap Utlization | D9: % | E9: =E10/E8 -> 0.058333333
C10: MS Rebars Produced / Sold | E10: ='Market Share'!E9*1000 -> 70000
C12: Rebar Export Sales % | D12: % | E12: 0
C13: Rebar Local Sales % | D13: % | E13: 1
C15: Rebar Export Selling Price | D15: USD | E15: 565
C16: Rebar Local Selling Price | D16: USD | E16: 677.69333
C17: Rebar Local Selling Price | D17: LE | E17: =E16*E5 -> 10978.632
C19: Produced Billet | D19: Tons | E19: =+E106 -> 72297.074
C20: EAF Yield | D20: % | E20: =+Billet!G17% -> 0.8735
C21: BCCM Yield | D21: % | E21: =+Billet!G18% -> 0.985
C22: Yield Rate | D22: % | E22: =+E20*E21 -> 0.8603975
C23: Solid Charge | D23: Tons | E23: =E19/E22 -> 84027.526
C25: Consumption
C26: Imported Scrap | D26: =+Billet!G15% -> 0.639867 | E26: =+D26*$E$23 -> 53766.441
C27: Local Scrap | D27: =+Billet!G14% -> 0.160133 | E27: =+D27*$E$23 -> 13455.58
C28: DRI | D28: =+Billet!G13% -> 0.2 | E28: =+D28*$E$23 -> 16805.505
C29: Home scrap | D29: 0 | E29: =+D29*$E$23 -> 0
C30: PIG IRON | D30: 0 | E30: =+D30*$E$23 -> 0
C32: Byproduct (scrap) | D32: -0.0080112177 | E32: =D32*E23 -> -673.1628
C34: Auxiliary Materials | D34: KG/ton | E34: =0.109025912856941*1000 -> 109.02591
C35: Refractories | D35: KG/ton | E35: 7.6715424
C36: Electrodes | D36: KG/ton | E36: 1.8285669
C37: Consumables | D37: KG/ton | E37: 1
C39: Electricity | D39: Kwh/ton | E39: =+Billet!G20+15.7308917064777 -> 612.83089
C40: Natural Gas | D40: Nm3/ton | E40: 14.208495
C41: Water | D41: M3/ton | E41: 0.99468845
C42: Oxygen | D42: Nm3/ton | E42: 22.875814
C43: Nitrogen | D43: Nm3/ton | E43: 1.0835797
C44: Chem | D44: Nm3/ton | E44: 1
C46: Handling Machine over max. Qty. | D46: KG/ton | E46: 1
C47: Cutting LTS | D47: KG/ton | E47: 1
C49: Unit Purchase Price
C50: Imported Scrap | D50: $/ton | E50: =+Billet!G10 -> 300
C51: Local Scrap | D51: $/ton | E51: =+Billet!G9 -> 300
C52: DRI | D52: $/ton | E52: =+Billet!G8 -> 274.66003
...

Sheet EZDK Wire
E2: Rebar Cost / Ton
E4: Base
C6: Exchange Rate | D6: EGP/USD | E6: =+Billet!D7 -> 16.2
C7: Inflation Rate | D7: % | E7: 0
C9: Rebars
C11: Total Rebar Production Capacity | D11: Tons | E11: 500000
C12: Capacity Utilization | D12: % | E12: 0.16079018
C13: Export Sales | D13: % | E13: =1-E14 -> 0
C14: Local Sales | D14: % | E14: 1
C16: Rebar Export Selling Price | D16: USD | E16: 0
C17: Rebar Local Selling Price | D17: LE | E17: 10743.186
C19: Rebars Yield | D19: % | E19: =+Wire!E6% -> 0.9761
C20: Rebar Production | D20: Tons | E20: =('Market Share'!F19+'Market Share'!F6)*1000 -> 50000
C21: Required Billets | D21: Tons | E21: =E20/E19 -> 51224.26
C23: Consumption
C24: Imported Billets Tons | D24: 0 | E24: =+D24*E21 -> 0
C25: Produced Billets Tons | D25: 1 | E25: =+D25*E21 -> 51224.26
C26: Local Billets Tons | D26: 0 | E26: =+D26*E21 -> 0
C27: By-product | D27: -0.018443095 | E27: =+D27*(E26+E25+E24) -> -944.73391
C28: Electricity | D28: Kwh/ton | E28: 117.84816
C29: Natural Gas | D29: Nm3/ton | E29: 30.6951
C30: N.Gas | D30: MMBTU/ton | E30: =E29/28 -> 1.0962536
C31: Recycled Water | D31: Nm3/ton | E31: 0.92902872
C32: Tying | D32: Kg/ton | E32: 1.8633484
C33: Chemicals | D33: Kg/ton | E33: 0.71357388
C34: Label & Rings | D34: Kg/ton | E34: 0.71357388
C35: Sp. Parts/Oil & Grease | D35: Kg/ton | E35: 0
C36: External Services | D36: Kg/ton | E36: 0
C38: Unit Price
C39: Imported Billets Purchase Price | D39: USD/ton | E39: 0
C40: Extra Cost | D40: LE/ton | E40: 0
C41: Landed Cost | D41: LE Eq/ton | E41: =(E6*E39)+E40 -> 0
C42: Good / Prod Billet Purchase Price | D42: LE/ton | E42: =+Wire!E12*E6 -> 7110.1767
C43: Local Billet Purchase Price | D43: LE/ton | E43: 0
C44: By Product Reduction | D44: LE/ton | E44: 5132.9268
C45: Electricity | D45: LE/KWH | E45: =0.07*E6 -> 1.134
C46: Natural Gas | D46: USD/MMBTU | E46: =+E47*28/E6 -> 7.3997061
C47: Natural Gas | D47: LE/NM3 | E47: 4.2812585
C48: Recycled Water | D48: LE/NM3 | E48: 13.174888
C49: Tying | D49: LE/Kg | E49: =11249.0074074074/1000 -> 11.249007
...

Sheet EZDK Flat
E2: ='[1]EFS MS Flat'!N2 -> Base
C3: Steel Making - Stage #1
C5: FX Rate | E5: =+Billet!D7 -> 16.2
C6: Inflation
C8: Rebar Production Cap | E8: 1200000
C9: Rebar Production Cap Utlization | D9: % | E9: 1
C10: HRC Produced / Sold | E10: =('Market Share'!G6+'Market Share'!G19)*1000 -> 85000
C12: Rebar Export Sales % | D12: % | E12: 0
C13: Rebar Local Sales % | D13: % | E13: 1
C15: Rebar Export Selling Price | D15: USD | E15: 565
C16: Rebar Local Selling Price | D16: USD | E16: 677.69333
C17: Rebar Local Selling Price | D17: LE | E17: =E16*E5 -> 10978.632
C19: Produced Molten Steel | D19: Tons | E19: =E106 -> 88138.192
C20: Yeild Rate | D20: % | E20: =+Flat!E17% -> 0.8522
C21: Solid Charge | D21: Tons | E21: =E19/E20 -> 103424.3
C23: Consumption
C24: Imported Scrap | D24: =+Flat!E15% -> 0.03 | E24: =D24*$E$21 -> 3102.7291
C25: Local Scrap | D25: =+Flat!E14% -> 0.16998 | E25: =D25*$E$21 -> 17580.063
C26: DRI | D26: =+Flat!E13% -> 0.8 | E26: =D26*$E$21 -> 82739.443
C27: Home scrap | D27: 0 | E27: =D27*$E$21 -> 0
C28: PIG IRON | D28: 0 | E28: =D28*$E$21 -> 0
C30: Byproduct (scrap) | D30: -0.032673411 | E30: =+D30*E21 -> -3379.2248
C32: Auxiliary Materials | D32: KG/ton | E32: 422.60159
C33: Refractories | D33: KG/ton | E33: 10.508598
C34: Electrodes | D34: KG/ton | E34: 2.5805617
C35: Other Fillers | D35: KG/ton | E35: 1.2842586
C37: Electricity (EAF & LF) | D37: KWH/Ton | E37: =+Flat!E20 -> 693.12
C38: Electricity (Aux - Airliq - Lime ) | D38: KWH/Ton | E38: 239.71539
C39: Natural Gas | D39: Nm3/ton | E39: 14.593054
C40: Water | D40: M3/ton | E40: 1.548884
C41: Oxygen | D41: Nm3/ton | E41: 34.797488
C42: Nitrogen | D42: Nm3/ton | E42: 4.0864981
C43: Aragon | D43: Nm3/ton | E43: 0.30455884
C45: Handling Machine over max. Qty. | D45: KG/ton | E45: 0.98684612
C46: Cutting LTS | D46: KG/ton | E46: 0
C48: Unit Purchase Price
C49: Imported Scrap | D49: $/ton | E49: =+Flat!E10 -> 275.51
C50: Local Scrap | D50: $/ton | E50: =+Flat!E9 -> 248.87
C51: DRI | D51: $/ton | E51: =+Flat!E8 -> 262.42129
C52: Home scrap | D52: $/ton | E52: 0
...

Sheet EFS Flat
E2: ='[1]EFS MS Flat'!N2 -> Base
C3: Steel Making - Stage #1
C5: FX Rate | E5: =+Billet!D7 -> 16.2
C6: Inflation
C8: Rebar Production Cap | E8: 1200000
C9: Rebar Production Cap Utlization | D9: % | E9: 1
C10: HRC Produced / Sold | E10: =('Market Share'!G20+'Market Share'!G7)*1000 -> 15000
C12: Rebar Export Sales % | D12: % | E12: 0.5
C13: Rebar Local Sales % | D13: % | E13: 0.5
C15: Rebar Export Selling Price | D15: USD | E15: 565
C16: Rebar Local Selling Price | D16: USD | E16: 677.69333
C17: Rebar Local Selling Price | D17: LE | E17: =E16*E5 -> 10978.632
C19: Produced Molten Steel | D19: Tons | E19: =E106 -> 15618.492
C20: Yeild Rate | D20: % | E20: =+Flat!F17% -> 0.8417
C21: Solid Charge | D21: Tons | E21: =E19/E20 -> 18555.89
C23: Consumption
C24: Imported Scrap | D24: =+Flat!F15% -> 0.05978 | E24: =D24*$E$21 -> 1109.2711
C25: Local Scrap | D25: =+Flat!F14% -> 0.14 | E25: =D25*$E$21 -> 2597.8245
C26: DRI | D26: =+Flat!F13% -> 0.8 | E26: =D26*$E$21 -> 14844.712
C27: Home scrap | D27: 0 | E27: =D27*$E$21 -> 0
C28: PIG IRON | D28: 0 | E28: =D28*$E$21 -> 0
C30: Byproduct (scrap) | D30: -0.032673411 | E30: =+D30*E21 -> -606.2842
C32: Auxiliary Materials | D32: KG/ton | E32: 422.60159
C33: Refractories | D33: KG/ton | E33: 10.508598
C34: Electrodes | D34: KG/ton | E34: 2.5805617
C35: Other Fillers | D35: KG/ton | E35: 1.2842586
C37: Electricity (EAF & LF) | D37: KWH/Ton | E37: =+Flat!F20 -> 708.39
C38: Electricity (Aux - Airliq - Lime ) | D38: KWH/Ton | E38: 239.71539
C39: Natural Gas | D39: Nm3/ton | E39: 14.593054
C40: Water | D40: M3/ton | E40: 1.548884
C41: Oxygen | D41: Nm3/ton | E41: 34.797488
C42: Nitrogen | D42: Nm3/ton | E42: 4.0864981
C43: Aragon | D43: Nm3/ton | E43: 0.30455884
C45: Handling Machine over max. Qty. | D45: KG/ton | E45: 0.98684612
C46: Cutting LTS | D46: KG/ton | E46: 0
C48: Unit Purchase Price
C49: Imported Scrap | D49: $/ton | E49: =+Flat!F10 -> 267.27
C50: Local Scrap | D50: $/ton | E50: =+Flat!F9 -> 248.87
C51: DRI | D51: $/ton | E51: =+Flat!F8 -> 267.30003
C52: Home scrap | D52: $/ton | E52: 0
...

Sheet Fixed Cost
B2: Total Monthly Fixed Cost | H2: =+TODAY() -> 46303
B4: Item | C4: Unit | D4: EZDK | E4: EFS | F4: ERM | G4: ESR | H4: Total Fixed
B6: Total Fixed Cost W/O Depretiation | C6: $ M | D6: =+SUM(D7:D9) -> 20.58 | E6: =+SUM(E7:E9) -> 6.22 | F6: =+SUM(F7:F9) -> 6.53 | G6: =+SUM(G7:G9) -> 10 | H6: =SUM(D6:G6) -> 43.33
B7: Manufacturing Fixed Cost | C7: $ M | D7: 9.93 | E7: 3.54 | F7: 1.17 | G7: 2.45 | H7: =SUM(D7:G7) -> 17.09
B8: SG&A | C8: $ M | D8: 3.66 | E8: 0.26 | F8: 0.84 | G8: 2.38 | H8: =SUM(D8:G8) -> 7.14
B9: Net Finance Cost | C9: $ M | D9: 6.99 | E9: 2.42 | F9: 4.52 | G9: 5.17 | H9: =SUM(D9:G9) -> 19.1
B11: Depretiation | C11: $ M | D11: 2.39 | E11: 2.52 | F11: 1.24 | G11: 0.13 | H11: =SUM(D11:G11) -> 6.28
B13: Total Monthly Fixed Cost including Depretiation | C13: $ M | D13: =D11+D6 -> 22.97 | E13: =E11+E6 -> 8.74 | F13: =F11+F6 -> 7.77 | G13: =G11+G6 -> 10.13 | H13: =H11+H6 -> 49.61
B15: USD Exchange rate | D15: 16.2
B17: Item | D17: EZDK | E17: EFS | F17: ERM | G17: ESR | H17: Total Fixed
B19: Total Fixed Cost W/O Depretiation | C19: LE M | D19: =D6*$D$15 -> 333.396 | E19: =E6*$D$15 -> 100.764 | F19: =F6*$D$15 -> 105.786 | G19: =G6*$D$15 -> 162 | H19: =SUM(D19:G19) -> 701.946
B20: Manufacturing Fixed Cost | C20: LE M | D20: =D7*$D$15 -> 160.866 | E20: =E7*$D$15 -> 57.348 | F20: =F7*$D$15 -> 18.954 | G20: =G7*$D$15 -> 39.69 | H20: =SUM(D20:G20) -> 276.858
B21: SG&A | C21: LE M | D21: =D8*$D$15 -> 59.292 | E21: =E8*$D$15 -> 4.212 | F21: =F8*$D$15 -> 13.608 | G21: =G8*$D$15 -> 38.556 | H21: =SUM(D21:G21) -> 115.668
B22: Net Finance Cost | C22: LE M | D22: =D9*$D$15 -> 113.238 | E22: =E9*$D$15 -> 39.204 | F22: =F9*$D$15 -> 73.224 | G22: =G9*$D$15 -> 83.754 | H22: =SUM(D22:G22) -> 309.42
B24: Depretiation | C24: LE M | D24: =D11*$D$15 -> 38.718 | E24: =E11*$D$15 -> 40.824 | F24: =F11*$D$15 -> 20.088 | G24: =G11*$D$15 -> 2.106 | H24: =SUM(D24:G24) -> 101.736
D26: 1 | E26: / 12
B28: Item | D28: EZDK | E28: EFS | F28: ERM | G28: ESR
B29: Fixed Cost Distribution
B30: DRI | C30: % | F30: 70
B31: Rebar | C31: % | D31: 25 | E31: 50 | F31: 30 | G31: 100
B32: Wire Rod | C32: % | D32: 25
B33: Flat | C33: % | D33: 50 | E33: 50
B34: Total | C34: % | D34: =SUM(D30:D33) -> 100 | E34: =SUM(E30:E33) -> 100 | F34: =SUM(F30:F33) -> 100 | G34: =SUM(G30:G33) -> 100
B36: DRI | D36: EZDK | E36: EFS | F36: ERM | G36: ESR | H36: Total
B38: Manufacturing Fixed Cost | C38: $ M | F38: =$F$30%*F7 -> 0.819 | H38: =SUM(D38:G38) -> 0.819
B39: SG&A | C39: $ M | F39: =$F$30%*F8 -> 0.588 | H39: =SUM(D39:G39) -> 0.588
B40: Net Finance Cost | C40: $ M | F40: =$F$30%*F9 -> 3.164 | H40: =SUM(D40:G40) -> 3.164
B41: Depretiation | C41: $ M | F41: =$F$30%*F11 -> 0.868 | H41: =SUM(D41:G41) -> 0.868
H42: =SUM(H38:H41) -> 5.439
B44: Rebar | D44: EZDK | E44: EFS | F44: ERM | G44: ESR | H44: Total
B46: Manufacturing Fixed Cost | C46: $ M | D46: =D$31%*D7 -> 2.4825 | E46: =E$31%*E7 -> 1.77 | F46: =F$31%*F7 -> 0.351 | G46: =G$31%*G7 -> 2.45 | H46: =SUM(D46:G46) -> 7.0535
B47: SG&A | C47: $ M | D47: =D$31%*D8 -> 0.915 | E47: =E$31%*E8 -> 0.13 | F47: =F$31%*F8 -> 0.252 | G47: =G$31%*G8 -> 2.38 | H47: =SUM(D47:G47) -> 3.677
B48: Net Finance Cost | C48: $ M | D48: =D$31%*D9 -> 1.7475 | E48: =E$31%*E9 -> 1.21 | F48: =F$31%*F9 -> 1.356 | G48: =G$31%*G9 -> 5.17 | H48: =SUM(D48:G48) -> 9.4835
B49: Depretiation | C49: $ M | D49: =D$31%*D11 -> 0.5975 | E49: =E$31%*E11 -> 1.26 | F49: =F$31%*F11 -> 0.372 | G49: =G$31%*G11 -> 0.13 | H49: =SUM(D49:G49) -> 2.3595
H50: =SUM(H46:H49) -> 22.5735
B52: Wire Rod | D52: EZDK | E52: EFS | F52: ERM | G52: ESR | H52: Total
B54: Manufacturing Fixed Cost | C54: $ M | D54: =D$32%*D7 -> 2.4825 | H54: =SUM(D54:G54) -> 2.4825
B55: SG&A | C55: $ M | D55: =D$32%*D8 -> 0.915 | H55: =SUM(D55:G55) -> 0.915
B56: Net Finance Cost | C56: $ M | D56: =D$32%*D9 -> 1.7475 | H56: =SUM(D56:G56) -> 1.7475
B57: Depretiation | C57: $ M | D57: =D$32%*D11 -> 0.5975 | H57: =SUM(D57:G57) -> 0.5975
...

Sheet DRI
B2: DRI Production Cost | F2: =+'Fixed Cost'!H2 -> 46303
B4: Item | C4: Unit | E4: EZDK | F4: ERM
B6: FX | C6: $/LE | E6: =+'Fixed Cost'!D15 -> 16.2
B8: IOP Landed Cost | C8: $/t | E8: 130 | F8: 136.62
B9: NG Price | C9: $/MMBTU | E9: 5.5 | F9: 5.5
B11: MRMR | C11: t/t | E11: 1.5 | F11: 1.43
B12: NG Consumption | C12: Nm3 | E12: 292.58 | F12: 333
B14: Variable Manufacturing Cost
B16: Material Prices | C16: $/t | E16: =+E8 -> 130 | F16: =+F8 -> 136.62
B18: MRMR Effect | C18: $/t | E18: =+(E11-1)*E16 -> 65 | F18: =+(F11-1)*F16 -> 58.7466
B19: Other Conversion Cost | C19: $/t | E19: =+SUM('DRI Cost'!E53:E61)/'DRI Cost'!E6 -> 67.421286 | F19: =+SUM('DRI Cost'!G53:G61)/'DRI Cost'!G6 -> 70.304901
B20: Total Conversion Cost | C20: $/t | E20: =+SUM(E18:E19) -> 132.42129 | F20: =+SUM(F18:F19) -> 129.0515
B22: Total Variable Manufacturing Cost | C22: $/t | E22: =+E20+E16 -> 262.42129 | F22: =+F20+F16 -> 265.6715
G24: =1+'Fixed Cost'!D26 -> 2 | H24: / 12

Sheet Billet
B2: Billet Production Cost | G2: =+DRI!F2 -> 46303
B4: Item | C4: Unit | E4: EZDK | F4: EFS | G4: ESR
B6: DRI Margin From ERM | C6: $/t | F6: 1.6285249 | G6: 8.9885249
B7: FX | C7: $/LE | D7: =+'Fixed Cost'!D15 -> 16.2
B8: DRI Price | C8: $/t | E8: =+DRI!E22 -> 262.42129 | F8: =+DRI!F22+(F6) -> 267.30003 | G8: =+DRI!F22+(G6) -> 274.66003
B9: Local Scrap Price | C9: $/t | E9: 300 | F9: 248.87 | G9: =+E9 -> 300
B10: Imported Scrap Landed Cost | C10: $/t | E10: 300 | F10: 267.27 | G10: =+E10 -> 300
B11: Elictricity Price | C11: $/KWH | E11: 0.07 | F11: 0.07 | G11: 0.007
B13: DRI Blending Ratio | C13: % | E13: 80 | F13: 80 | G13: 20
B14: Local Scrap | C14: % | E14: 4 | F14: 14 | G14: 16.0133
B15: Imported Scrap | C15: % | E15: 15.977 | F15: 5.978 | G15: 63.9867
B17: EAF Yield | C17: % | E17: 84.93 | F17: 84.17 | G17: 87.35
B18: CCP Yield | C18: % | E18: 99.38 | F18: 98.05 | G18: 98.5
B19: Billet yield from Solid Charge | C19: % | E19: =+E18*E17/100 -> 84.403434 | F19: =+F18*F17/100 -> 82.528685 | G19: =+G18*G17/100 -> 86.03975
B20: EAF & LF Electricity Consumption | C20: KWH/tms | E20: 713.63 | F20: 708.39 | G20: 597.1
B22: Variable Manufacturing Cost
B24: Material Price | C24: $/t | E24: =E8*E13%+E9*E14%+E10*E15% -> 269.86803 | F24: =F8*F13%+F9*F14%+F10*F15% -> 264.65922 | G24: =G8*G13%+G9*G14%+G10*G15% -> 294.93201
B26: Yield Effect | C26: $/t | E26: =+((1/(E17%*E18%)-1)*E8*E13%+((1/(E17%*E18%)-1))*E9*E14%+((1/(E17%*E18%))-1)*E10*E15%) -> 49.867811 | F26: =+((1/(F17%*F18%)-1)*F8*F13%+((1/(F17%*F18%)-1))*F9*F14%+((1/(F17%*F18%))-1)*F10*F15%) -> 56.028333 | G26: =+((1/(G17%*G18%)-1)*G8*G13%+((1/(G17%*G18%)-1))*G9*G14%+((1/(G17%*G18%))-1)*G10*G15%) -> 47.853748
B27: Other Conversion Cost | C27: $/t | E27: =+'EZDK Rebar'!J270 -> 119.16396 | F27: =+'EFS Rebar'!J270 -> 130.70155 | G27: =+SUM('ESR Rebar'!E80:E95) -> 120.68528
B28: Total Conversion Cost | C28: $/t | E28: =+E26+E27 -> 169.03177 | F28: =+F26+F27 -> 186.72988 | G28: =+G26+G27 -> 168.53902
B30: Total Variable Manufacturing Cost | C30: $/t | E30: =+E28+E24 -> 438.8998 | F30: =+F28+F24 -> 451.38911 | G30: =+G28+G24 -> 463.47103
B33: Items | C33: Units | E33: EZDK | F33: EFS | G33: ERM | H33: ESR | K33: =G24*16.3 -> 4807.3917
K34: =(G28+21)*16.3 -> 3089.4861
B35: Billet Trade off | E35: 1.0410868 | F35: 1.0384615 | H35: 1.0404568
B36: Landed Cost | E36: 1.0174193
B38: Source
B39: EZDK | C39: $/t | E39: =+E30 -> 438.8998 | F39: =+E30*E35 -> 456.93279 | G39: 429.88 | H39: =+E30*E35 -> 456.93279
B40: EFS | C40: $/t | E40: =+F30*F35 -> 468.75023 | F40: =+F30 -> 451.38911 | G40: =+F30*F35 -> 468.75023 | H40: =+F30*F35 -> 468.75023
B41: ESR | C41: $/t | E41: =+G30*H35 -> 482.22157 | F41: =+G30*H35 -> 482.22157 | G41: =+G30*(H35) -> 482.22157 | H41: =+G30 -> 463.47103
B42: Market | C42: $/t | E42: =+E52 -> 514.36 | F42: =E52 -> 514.36 | G42: =E52 -> 514.36 | H42: =E52 -> 514.36
B44: Minimum Billet Cost | C44: $/t | E44: =MIN(E39:E42) -> 438.8998 | F44: =MIN(F39:F42) -> 451.38911 | G44: =MIN(G39:G42) -> 429.88 | H44: =MIN(H39:H42) -> 456.93279
B46: Market Billet
B48: Base | C48: $/t | E48: 428
B49: Safe Guardes | C49: $/t | E49: 74
B50: Other Costs | C50: $/t | E50: 12.36
B52: Market Price for Billet | C52: $/t | E52: =+SUM(E48:E50) -> 514.36
H54: =1+DRI!G24 -> 3 | I54: / 12

Sheet Rebar
B2: Rebar Productiom | H2: =+Billet!G2 -> 46303
B4: Items | C4: Units | E4: EZDK | F4: EFS | G4: ERM | H4: ESR
B6: Rebar Yield | C6: % | E6: 93.62 | F6: 97.09 | G6: 97.917872 | H6: 96.822729
B8: Sc1 In-house billet
B10: Variable Manufacturing Cost
B12: Material Price | C12: $/t | E12: =+Billet!E30 -> 438.8998 | F12: =+Billet!F30 -> 451.38911 | G12: =+Billet!E30 -> 438.8998 | H12: =+Billet!G30 -> 463.47103
B14: Yeild Effect | C14: $/t | E14: =+E12*((1/E6%)-1) -> 29.91007 | F14: =+F12*((1/F6%)-1) -> 13.52912 | G14: =+G12*((1/G6%)-1) -> 9.3327737 | H14: =+H12*((1/H6%)-1) -> 15.208958
B15: Home Scrap Deduction | C15: $/t | E15: =+'EZDK Rebar'!E193 -> -15.88 | F15: =+'EFS Rebar'!E193 -> -7.24 | G15: =+'ERM Rolling'!E64/'ERM Rolling'!E6 -> -5.2317308 | H15: =+'ESR Rebar'!E146 -> -7.91
B16: Other Conversion Cost | C16: $/t | E16: =+SUM('EZDK Rebar'!E195:E201) -> 16.15312 | F16: =+SUM('EFS Rebar'!E195:E199) -> 12.116607 | G16: =+'ERM Rolling'!E77/'ERM Rolling'!E6 -> 17.008738 | H16: =SUM('ESR Rebar'!E149:E157) -> 14.946021
B17: Total Conversion Cost | C17: $/t | E17: =+E16+E15+E14 -> 30.183189 | F17: =+F16+F15+F14 -> 18.405727 | G17: =+G16+G15+G14 -> 21.109781 | H17: =+H16+H15+H14 -> 22.244979
B19: Total Variable Manufacturing Cost | C19: $/t | E19: =+E17+E12 -> 469.08299 | F19: =+F17+F12 -> 469.79483 | G19: =+G17+G12 -> 460.00958 | H19: =+H17+H12 -> 485.71601
B21: Sc2 In-house billet
B23: Variable Manufacturing Cost
B25: Material Price | C25: $/t | E25: =+Billet!$E$52 -> 514.36 | F25: =+Billet!$E$52 -> 514.36 | G25: =+Billet!$E$52 -> 514.36 | H25: =+Billet!$E$52 -> 514.36
B27: Yeild Effect | C27: $/t | E27: =+E25*((1/E6%)-1) -> 35.052519 | F27: =+F25*((1/F6%)-1) -> 15.416496 | G27: =+G25*((1/G6%)-1) -> 10.937361 | H27: =+H25*((1/H6%)-1) -> 16.878897
B28: Home Scrap Deduction | C28: $/t | E28: =+E15 -> -15.88 | F28: =+F15 -> -7.24 | G28: =+G15 -> -5.2317308 | H28: =+H15 -> -7.91
B29: Other Conversion Cost | C29: $/t | E29: =+E16 -> 16.15312 | F29: =+F16 -> 12.116607 | G29: =+G16 -> 17.008738 | H29: =+H16 -> 14.946021
B30: Total Conversion Cost | C30: $/t | E30: =+E29+E28+E27 -> 35.325638 | F30: =+F29+F28+F27 -> 20.293103 | G30: =+G29+G28+G27 -> 22.714368 | H30: =+H29+H28+H27 -> 23.914918
B32: Total Variable Manufacturing Cost | C32: $/t | E32: =+E30+E25 -> 549.68564 | F32: =+F30+F25 -> 534.6531 | G32: =+G30+G25 -> 537.07437 | H32: =+H30+H25 -> 538.27492
B34: Difference | C34: $/t | E34: =+E19-E32 -> -80.60265 | F34: =+F19-F32 -> -64.85827 | G34: =+G19-G32 -> -77.064788 | H34: =+H19-H32 -> -52.558909
H36: =1+Billet!H54 -> 4 | I36: / 12

Sheet Wire
B2: Wire Rod Productiom | E2: =+Billet!G2 -> 46303
B4: Items | C4: Units | E4: EZDK
B6: Rebar Yield | C6: % | E6: 97.61
B8: Sc1 In-house billet
B10: Variable Manufacturing Cost
B12: Material Price | C12: $/t | E12: =+Billet!E30 -> 438.8998
B14: Yeild Effect | C14: $/t | E14: =+E12*((1/E6%)-1) -> 10.746548
B15: Home Scrap Deduction | C15: $/t | E15: =+'EZDK Wire'!E64/'EZDK Wire'!E6 -> -5.9867284
B16: Other Conversion Cost | C16: $/t | E16: =+'EZDK Wire'!E77/'EZDK Wire'!E6 -> 18.87316
B17: Total Conversion Cost | C17: $/t | E17: =+E16+E15+E14 -> 23.632979
B19: Total Variable Manufacturing Cost | C19: $/t | E19: =+E17+E12 -> 462.53278
B21: Sc2 In-house billet
B23: Variable Manufacturing Cost
B25: Material Price | C25: $/t | E25: =+Billet!$E$52 -> 514.36
B27: Yeild Effect | C27: $/t | E27: =+E25*((1/E6%)-1) -> 12.594206
B28: Home Scrap Deduction | C28: $/t | E28: =+E15 -> -5.9867284
B29: Other Conversion Cost | C29: $/t | E29: =+E16 -> 18.87316
B30: Total Conversion Cost | C30: $/t | E30: =+E29+E28+E27 -> 25.480637
B32: Total Variable Manufacturing Cost | C32: $/t | E32: =+E30+E25 -> 539.84064
B34: Difference | C34: $/t | E34: =+E19-E32 -> -77.307859
E36: =1+Rebar!H36 -> 5 | F36: / 12

Sheet Flat
B2: HRC Production Cost | F2: =+DRI!F2 -> 46303
B4: Item | C4: Unit | E4: EZDK | F4: EFS
B6: DRI Margin From ERM | C6: $/t | F6: 1.6285249
B7: FX | C7: $/LE | D7: =+DRI!E6 -> 16.2
B8: DRI Price | C8: $/t | E8: =+DRI!E22 -> 262.42129 | F8: =+DRI!F22+F6 -> 267.30003
B9: Local Scrap Price | C9: $/t | E9: 248.87 | F9: 248.87
B10: Imported Scrap Landed Cost | C10: $/t | E10: 275.51 | F10: 267.27
B11: Elictricity Price | C11: $/KWH | E11: 0.07 | F11: 0.07
B13: DRI Blending Ratio | C13: % | E13: 80 | F13: 80
B14: Local Scrap | C14: % | E14: 16.998 | F14: 14
B15: Imported Scrap | C15: % | E15: 3 | F15: 5.978
B17: EAF Yield | C17: % | E17: 85.22 | F17: 84.17
B18: TSC Yield | C18: % | E18: 98.73 | F18: 98
B19: HSM Yield | C19: % | E19: 97.68 | F19: 98
B20: EAF & LF Electricity Consumption | C20: KWH/tms | E20: 693.12 | F20: 708.39
B22: Variable Manufacturing Cost
B24: Material Price | C24: $/t | E24: =E8*E13%+E9*E14%+E10*E15% -> 260.50525 | F24: =F8*F13%+F9*F14%+F10*F15% -> 264.65922
B26: Yield Effect | C26: $/t | E26: =+((1/(E17%*E18%*E19%)-1)*E8*E13%+((1/(E17%*E18%*E19%)-1))*E9*E14%+((1/(E17%*E18%*E19%))-1)*E10*E15%) -> 56.466212 | F26: =+((1/(F17%*F18%*F19%)-1)*F8*F13%+((1/(F17%*F18%*F19%)-1))*F9*F14%+((1/(F17%*F18%*F19%))-1)*F10*F15%) -> 62.739932
B27: Other Conversion Cost | C27: $/t | E27: =+'EZDK Flat'!J269 -> 125.9086 | F27: =+'EFS Flat'!J269 -> 151.84056
B28: Total Conversion Cost | C28: $/t | E28: =+E26+E27 -> 182.37482 | F28: =+F26+F27 -> 214.58049
B30: Total Variable Manufacturing Cost | C30: $/t | E30: =+E28+E24 -> 442.88007 | F30: =+F28+F24 -> 479.23971
F32: =1+Wire!E36 -> 6 | G32: / 12

Sheet Market Share
B2: Monthly Market Share | G2: =+Flat!F2 -> 46303
B4: Item | C4: Units | E4: Rebar | F4: Wire Rod | G4: HRC
B6: EZDK | C6: Ktons | E6: 100 | F6: 40 | G6: 45
B7: EFS | C7: Ktons | E7: 70 | G7: 7.5
B8: ERM | C8: Ktons | E8: 30
B9: ESR | C9: Ktons | E9: 70
B11: Group Local Sales Quantity | C11: Ktons | E11: =SUM(E6:E9) -> 270 | F11: =+F6 -> 40 | G11: =SUM(G22:G23) -> 0
B12: Ezz Steel market Share | C12: % | E12: =+E11/E22*100 -> 51.428571 | F12: =+F11/F22*100 -> 53.333333 | H12: Ezz Steel
E13: =100-E12 -> 48.571429 | F13: =100-F12 -> 46.666667 | H13: Other
B14: EZDK % from Group sales | C14: % | E14: =+E6/E11*100 -> 37.037037 | F14: =+F6/F11*100 -> 100 | G14: =+G6/G11*100 -> #DIV/0!
B15: EFS % from Group sales | C15: % | E15: =E7/E11*100 -> 25.925926 | G15: =+G7/G11*100 -> #DIV/0!
B16: ERM % from Group sales | C16: % | E16: =+E8/E11*100 -> 11.111111
B17: ESR % from Group sales | C17: % | E17: =+E9/E11*100 -> 25.925926
B19: EZDK Export | C19: Ktons | F19: 10 | G19: 40
B20: EFS Export | C20: Ktons | G20: 7.5
B22: Total Local Market | C22: Ktons | E22: 525 | F22: 75 | G22: N/A
B25: Selling Prices | C25: Units | E25: Rebar | F25: Wire Rod | G25: HRC
B27: FX | D27: =+'Fixed Cost'!D15 -> 16.2
B29: EZDK | C29: LE/ton | E29: 9300 | F29: 9075 | G29: 8900
B30: EFS | C30: LE/ton | E30: 9300 | G30: 8900
B31: ERM | C31: LE/ton | E31: 9300
B32: ESR | C32: LE/ton | E32: 9300
B34: EZDK | C34: $/ton | E34: 490 | F34: 480 | G34: 510
B35: EFS | C35: $/ton | E35: 490 | G35: 510
B36: ERM | C36: $/ton | E36: 490
B37: ESR | C37: $/ton | E37: 490
E39: =1+Flat!F32 -> 7 | F39: / 12

Sheet Production Requirments
B2: Monthly Production requirment | I2: ='Market Share'!G2 -> 46303
B4: Item | C4: Unit | E4: EZDK | F4: EFS | G4: ERM | H4: ESR | I4: Total
B6: 1 - Long Production Line
B7: Rebars | C7: Ktons | E7: ='Market Share'!E6 -> 100 | F7: ='Market Share'!E7 -> 70 | G7: ='Market Share'!E8 -> 30 | H7: ='Market Share'!E9 -> 70 | I7: =SUM(E7:H7) -> 270
B8: Wire Rod | C8: Ktons | E8: ='Market Share'!F6+'Market Share'!F19 -> 50 | I8: =SUM(E8:H8) -> 50
B10: Billet | C10: Ktons | E10: =+'EZDK Rebar'!E104/1000 -> 158.03904 | F10: ='EFS Rebar'!E104/1000 -> 72.098053 | G10: =+'ERM Rolling'!E21/1000 -> 30.637921 | H10: ='ESR Rebar'!E19/1000 -> 72.297074 | I10: =SUM(E10:H10) -> 333.07209
B11: Molten Steel | C11: Ktons | E11: ='EZDK Rebar'!E19/1000 -> 159.025 | F11: ='EFS Rebar'!E106/1000 -> 73.531926 | H11: =H10/'ESR Rebar'!E21 -> 73.398044 | I11: =SUM(E11:H11) -> 305.95497
B12: EAF Solid Charge (W/O Aux & Alloys) | C12: Ktons | E12: ='EZDK Rebar'!E21/1000 -> 187.24243 | F12: ='EFS Rebar'!E21/1000 -> 87.361205 | H12: ='ESR Rebar'!E23/1000 -> 84.027526 | I12: =SUM(E12:H12) -> 358.63116
B13: DRI Blending Ratio | C13: % | E13: ='EZDK Rebar'!D26 -> 0.8 | F13: ='EFS Rebar'!D26 -> 0.8 | H13: ='ESR Rebar'!D28 -> 0.2
B14: DRI | C14: Ktons | E14: ='EZDK Rebar'!E26/1000 -> 149.79395 | F14: ='EFS Rebar'!E26/1000 -> 69.888964 | H14: ='ESR Rebar'!E28/1000 -> 16.805505 | I14: =SUM(E14:H14) -> 236.48841
B15: Imported Scrap Blending Ratio | C15: % | E15: ='EZDK Rebar'!D24 -> 0.15977 | F15: ='EFS Rebar'!D24 -> 0.05978 | H15: ='ESR Rebar'!D26 -> 0.639867
B16: Imported Scrap | C16: Ktons | E16: ='EZDK Rebar'!E24/1000 -> 29.915723 | F16: ='EFS Rebar'!E24/1000 -> 5.2224528 | H16: ='ESR Rebar'!E26/1000 -> 53.766441 | I16: =SUM(E16:H16) -> 88.904617
B17: Local Scrap Blending Ratio | C17: % | E17: ='EZDK Rebar'!D25 -> 0.04 | F17: ='EFS Rebar'!D25 -> 0.14 | H17: ='ESR Rebar'!D27 -> 0.160133
B18: local Scrap | C18: Ktons | E18: ='EZDK Rebar'!E25/1000 -> 7.4896973 | F18: ='EFS Rebar'!E25/1000 -> 12.230569 | H18: ='ESR Rebar'!E27/1000 -> 13.45558 | I18: =SUM(E18:H18) -> 33.175846
B20: MRMR | C20: ton/ton | E20: ='DRI Cost'!E15 -> 1.5 | G20: ='DRI Cost'!G15 -> 1.43
B21: IOP | C21: Ktons | E21: =E14*E20 -> 224.69092 | G21: =(F14+H14)*G20 -> 123.97309 | I21: =SUM(E21:H21) -> 348.66401
B23: 2 - Flat Production Line
B24: HRC | C24: Ktons | E24: =('EZDK Flat'!E10)/1000 -> 85 | F24: ='EFS Flat'!E10/1000 -> 15 | I24: =SUM(E24:H24) -> 100
B26: Molten steel | C26: Ktons | E26: ='EZDK Flat'!E19/1000 -> 88.138192 | F26: ='EFS Flat'!E19/1000 -> 15.618492 | I26: =SUM(E26:H26) -> 103.75668
B27: EAF Solid Charge (W/O Aux & Alloys) | C27: Ktons | E27: ='EZDK Flat'!E21/1000 -> 103.4243 | F27: ='EFS Flat'!E21/1000 -> 18.55589 | I27: =SUM(E27:H27) -> 121.98019
B28: DRI Blending Ratio | C28: % | E28: ='EZDK Flat'!D26 -> 0.8 | F28: ='EFS Flat'!D26 -> 0.8
B29: DRI | C29: Ktons | E29: ='EZDK Flat'!E26/1000 -> 82.739443 | F29: ='EFS Flat'!E26/1000 -> 14.844712 | I29: =SUM(E29:H29) -> 97.584155
B30: Imported Scrap Blending Ratio | C30: % | E30: ='EZDK Flat'!D24 -> 0.03 | F30: ='EFS Flat'!D24 -> 0.05978
B31: Imported Scrap | C31: Ktons | E31: ='EZDK Flat'!E24/1000 -> 3.1027291 | F31: ='EFS Flat'!E24/1000 -> 1.1092711 | I31: =SUM(E31:H31) -> 4.2120002
B32: Local Scrap Blending Ratio | C32: % | E32: ='EZDK Flat'!D25 -> 0.16998 | F32: ='EFS Flat'!D25 -> 0.14
B33: local Scrap | C33: Ktons | E33: ='EZDK Flat'!E25/1000 -> 17.580063 | F33: ='EFS Flat'!E25/1000 -> 2.5978245 | I33: =SUM(E33:H33) -> 20.177888
B35: MRMR | C35: ton/ton | E35: ='DRI Cost'!E15 -> 1.5 | G35: ='DRI Cost'!G15 -> 1.43
B36: IOP | C36: Ktons | E36: =E29*E35 -> 124.10917 | G36: =F29*G35 -> 21.227938 | I36: =SUM(E36:H36) -> 145.3371
B38: Monthly Production Summary
B39: Rebar | C39: Ktons | E39: =E7 -> 100 | F39: =F7 -> 70 | G39: =+G7 -> 30 | H39: =H7 -> 70 | I39: =SUM(E39:H39) -> 270
B40: Wire Rod | C40: Ktons | E40: =E8 -> 50 | I40: =SUM(E40:H40) -> 50
B41: HRC | C41: Ktons | E41: =E24 -> 85 | F41: =F24 -> 15 | I41: =SUM(E41:H41) -> 100
B42: Billet | C42: Ktons | E42: =E10 -> 158.03904 | F42: =F10 -> 72.098053 | G42: =+G10 -> 30.637921 | H42: =H10 -> 72.297074 | I42: =SUM(E42:H42) -> 333.07209
B43: DRI | C43: Ktons | E43: =E29+E14 -> 232.53339 | F43: =F29+F14 -> 84.733675 | H43: =H29+H14 -> 16.805505 | I43: =SUM(E43:H43) -> 334.07257
B44: IOP | C44: Ktons | E44: =E21+E36 -> 348.80008 | G44: =G21+G36 -> 145.20103 | I44: =SUM(E44:H44) -> 494.00111
B45: Scrap | C45: Ktons | E45: =E16+E18+E31+E33 -> 58.088213 | F45: =F16+F18+F31+F33 -> 21.160117 | H45: =H16+H18+H31+H33 -> 67.222021 | I45: =SUM(E45:H45) -> 146.47035
H47: =1+'Market Share'!E39 -> 8 | I47: / 12

Sheet P&L $ Monthly
B2: P & L Statement per month USD
E4: EZDK | J4: EFS | N4: ERM | P4: ESR | R4: Total
B5: Items | C5: Unit | E5: Rebar | F5: Wire Rod | G5: HRC | H5: Sub-Total | J5: Rebar | K5: HRC | L5: Sub-Total | N5: Rebar | P5: Rebar
B7: Local Sales | C7: Ktons | E7: =+'Market Share'!E6 -> 100 | F7: =+'Market Share'!F6 -> 40 | G7: =+'Market Share'!G6 -> 45 | H7: =SUM(E7:G7) -> 185 | J7: =+'Market Share'!E7 -> 70 | K7: =+'Market Share'!G7 -> 7.5 | L7: =SUM(J7:K7) -> 77.5 | N7: =+'Market Share'!E8 -> 30 | P7: =+'Market Share'!E9 -> 70 | R7: =+P7+L7+H7+N7 -> 362.5
B8: Export Sales | C8: Ktons | E8: =+'Market Share'!E19 -> 0 | F8: =+'Market Share'!F19 -> 10 | G8: =+'Market Share'!G19 -> 40 | H8: =SUM(E8:G8) -> 50 | J8: =+'Market Share'!E20 -> 0 | K8: =+'Market Share'!G20 -> 7.5 | L8: =SUM(J8:K8) -> 7.5 | N8: 0 | P8: 0 | R8: =+P8+L8+H8+N8 -> 57.5
B9: Total Sales Quantity | C9: Ktons | E9: =SUM(E7:E8) -> 100 | F9: =SUM(F7:F8) -> 50 | G9: =SUM(G7:G8) -> 85 | H9: =SUM(H7:H8) -> 235 | J9: =SUM(J7:J8) -> 70 | K9: =SUM(K7:K8) -> 15 | L9: =SUM(L7:L8) -> 85 | N9: =SUM(N7:N8) -> 30 | P9: =SUM(P7:P8) -> 70 | R9: =+P9+L9+H9+N9 -> 420
B11: Local Sales Value | C11: M $ | E11: =+E12*E7/1000 -> 57.407407 | F11: =F12*F7/1000 -> 22.407407 | G11: =G12*G7/1000 -> 24.722222 | H11: =SUM(E11:G11) -> 104.53704 | J11: =J12*J7/1000 -> 40.185185 | K11: =+K12*K7/1000 -> 4.1203704 | L11: =SUM(J11:K11) -> 44.305556 | N11: =N12*N7/1000 -> 17.222222 | P11: =+P12*P9/1000 -> 40.185185 | R11: =+P11+L11+H11+N11 -> 206.25
B12: Price per unit | C12: $/t | E12: =+'Market Share'!E29/'Market Share'!D27 -> 574.07407 | F12: =+'Market Share'!F29/'Market Share'!D27 -> 560.18519 | G12: =+'Market Share'!G29/'Market Share'!D27 -> 549.38272 | H12: =+H11/H7*1000 -> 565.06507 | J12: =+'Market Share'!E30/'Market Share'!D27 -> 574.07407 | K12: =+'Market Share'!G30/'Market Share'!D27 -> 549.38272 | L12: =+L11/L7*1000 -> 571.68459 | N12: =+'Market Share'!E31/'Market Share'!D27 -> 574.07407 | P12: =+'Market Share'!E32/'Market Share'!D27 -> 574.07407 | R12: =+R11/R7*1000 -> 568.96552
B13: Export Sales Value | C13: M $ | E13: =E14*E8/1000 -> 0 | F13: =F14*F8/1000 -> 4.8 | G13: =+G14*G8/1000 -> 20.4 | H13: =SUM(E13:G13) -> 25.2 | J13: 0 | K13: =+K14*K8/1000 -> 3.825 | L13: =+SUM(J13:K13) -> 3.825 | N13: 0 | P13: 0 | R13: =+P13+L13+H13+N13 -> 29.025
B14: Price per unit | C14: $/t | E14: =+'Market Share'!E34 -> 490 | F14: =+'Market Share'!F34 -> 480 | G14: =+'Market Share'!G34 -> 510 | H14: =+H13/H8*1000 -> 504 | J14: 0 | K14: =+'Market Share'!G35 -> 510 | L14: 0 | N14: 0 | P14: 0 | R14: =+R13/R8*1000 -> 504.78261
B15: Total Sales Value | C15: M $ | E15: =+E13+E11 -> 57.407407 | F15: =+F13+F11 -> 27.207407 | G15: =+G13+G11 -> 45.122222 | H15: =SUM(E15:G15) -> 129.73704 | J15: =+J13+J11 -> 40.185185 | K15: =+K13+K11 -> 7.9453704 | L15: =SUM(J15:K15) -> 48.130556 | N15: =+N13+N11 -> 17.222222 | P15: =+P13+P11 -> 40.185185 | R15: =+P15+L15+H15+N15 -> 235.275
B16: Average price per unit | C16: $/t | E16: =+E15*1000/(E9) -> 574.07407 | F16: =F15/F9*1000 -> 544.14815 | G16: =+G15/G9*1000 -> 530.84967 | H16: =+H15/H9*1000 -> 552.0725 | J16: =+J15*1000/(J9) -> 574.07407 | K16: =+K15*1000/(K9) -> 529.69136 | L16: =+L15/L9*1000 -> 566.24183 | N16: =+N15*1000/(N9) -> 574.07407 | P16: =P15/P9*1000 -> 574.07407 | R16: =+R15/R9*1000 -> 560.17857
B18: Varible COGS | C18: M $ | E18: =(+E19*E9)/1000 -> 46.908445 | F18: =+F19*F9/1000 -> 23.126639 | G18: =+G19*G9/1000 -> 37.644925 | H18: =SUM(E18:G18) -> 107.68001 | J18: =J19*J9/1000 -> 32.885737 | K18: =K19*K9/1000 -> 7.1886167 | L18: =SUM(J18:K18) -> 40.074354 | N18: =N19*N9/1000 -> 13.800287 | P18: =P19*P9/1000 -> 34.000121 | R18: =+P18+L18+H18+N18 -> 195.55477
B19: Cost per unit | C19: $/t | E19: =+'EZDK Rebar'!E205 -> 469.08445 | F19: =+'EZDK Wire'!E86/'EZDK Wire'!E6 -> 462.53278 | G19: =+'EZDK Flat'!E205 -> 442.88147 | H19: =+H18/H9*1000 -> 458.21281 | J19: =+'EFS Rebar'!E205 -> 469.79625 | K19: ='EFS Flat'!E205 -> 479.24112 | L19: =+L18/L9*1000 -> 471.46299 | N19: =+'ERM Rolling'!E86/'ERM Rolling'!E6 -> 460.00958 | P19: ='ESR Rebar'!E161 -> 485.71601 | R19: =+R18/R9*1000 -> 465.6066
B21: Exporting expences | C21: $/t | E21: 0 | F21: 0.2 | G21: 0.8 | H21: =SUM(E21:G21) -> 1 | J21: 0 | K21: 0.15 | L21: =+K21 -> 0.15 | N21: 0 | P21: 0 | R21: =+P21+L21+H21+N21 -> 1.15
B23: Contribution Margin value | C23: M $ | E23: =E15-E18-E21 -> 10.498962 | F23: =F15-F18-F21 -> 3.8807685 | G23: =G15-G18-G21 -> 6.677297 | H23: =SUM(E23:G23) -> 21.057027 | J23: =J15-J18-J21 -> 7.2994479 | K23: =K15-K18-K21 -> 0.60675363 | L23: =SUM(I23:K23) -> 7.9062015 | N23: =N15-N18-N21 -> 3.4219348 | P23: =P15-P18-P21 -> 6.1850645 | R23: =+P23+L23+H23+N23 -> 38.570228
B24: CM per unit | C24: $/t | E24: =E23*1000/E9 -> 104.98962 | F24: =F23*1000/F9 -> 77.61537 | G24: =G23*1000/G9 -> 78.556435 | H24: =+H23/H9*1000 -> 89.604372 | J24: =J23*1000/J9 -> 104.27783 | K24: =K23*1000/K9 -> 40.450242 | L24: =+L23/L9*1000 -> 93.014135 | N24: =N23*1000/N9 -> 114.06449 | P24: =P23*1000/P9 -> 88.358065 | R24: =+R23/R9*1000 -> 91.833877
B25: Margin | C25: % | E25: =E24/E16*100 -> 18.288514 | F25: =F24/F16*100 -> 14.263647 | G25: =G24/G16*100 -> 14.798245 | H25: =H24/H16*100 -> 16.230544 | J25: =J24/J16*100 -> 18.164525 | K25: =K24/K16*100 -> 7.6365682 | L25: =L24/L16*100 -> 16.426574 | N25: =N24/N16*100 -> 19.869299 | P25: =P24/P16*100 -> 15.391405 | R25: =R24/R16*100 -> 16.393679
B27: Intercompany Gains
B28: DRI | C28: M $ | N28: 0.17 | R28: =+N28 -> 0.17
B29: Billet | C29: M $
B31: Manufacturing Fixed Cost | C31: M $ | E31: =+'Fixed Cost'!D46 -> 2.4825 | F31: =+'Fixed Cost'!D54 -> 2.4825 | G31: =+'Fixed Cost'!D62 -> 4.965 | H31: =SUM(E31:G31) -> 9.93 | J31: =+'Fixed Cost'!E46 -> 1.77 | K31: =+'Fixed Cost'!E62 -> 1.77 | L31: =SUM(I31:K31) -> 3.54 | N31: =+'Fixed Cost'!F7 -> 1.17 | P31: =+'Fixed Cost'!G46 -> 2.45 | R31: =+P31+L31+H31+N31 -> 17.09
B32: SG&A | C32: M $ | E32: =+'Fixed Cost'!D47 -> 0.915 | F32: =+'Fixed Cost'!D55 -> 0.915 | G32: =+'Fixed Cost'!D63 -> 1.83 | H32: =SUM(E32:G32) -> 3.66 | J32: =+'Fixed Cost'!E47 -> 0.13 | K32: =+'Fixed Cost'!E63 -> 0.13 | L32: =SUM(I32:K32) -> 0.26 | N32: =+'Fixed Cost'!F8 -> 0.84 | P32: =+'Fixed Cost'!G47 -> 2.38 | R32: =+P32+L32+H32+N32 -> 7.14
B33: Net Financing Cost | C33: M $ | E33: =+'Fixed Cost'!D48 -> 1.7475 | F33: =+'Fixed Cost'!D56 -> 1.7475 | G33: =+'Fixed Cost'!D64 -> 3.495 | H33: =SUM(E33:G33) -> 6.99 | J33: =+'Fixed Cost'!E48 -> 1.21 | K33: =+'Fixed Cost'!E64 -> 1.21 | L33: =SUM(I33:K33) -> 2.42 | N33: =+'Fixed Cost'!F9 -> 4.52 | P33: =+'Fixed Cost'!G48 -> 5.17 | R33: =+P33+L33+H33+N33 -> 19.1
B34: Total Fixed Exp | C34: M $ | E34: =SUM(E31:E33) -> 5.145 | F34: =SUM(F31:F33) -> 5.145 | G34: =SUM(G31:G33) -> 10.29 | H34: =SUM(E34:G34) -> 20.58 | J34: =SUM(J31:J33) -> 3.11 | K34: =SUM(K31:K33) -> 3.11 | L34: =SUM(I34:K34) -> 6.22 | N34: =SUM(N31:N33) -> 6.53 | P34: =SUM(P31:P33) -> 10 | R34: =+P34+L34+H34+N34 -> 43.33
B36: Cash Earning before Tax & Dep | C36: M $ | E36: =E23-E34 -> 5.3539619 | F36: =F23-F34 -> -1.2642315 | G36: =G23-G34 -> -3.612703 | H36: =SUM(E36:G36) -> 0.47702738 | J36: =J23-J34 -> 4.1894479 | K36: =K23-K34 -> -2.5032464 | L36: =SUM(I36:K36) -> 1.6862015 | N36: =N23+N28-N34 -> -2.9380652 | P36: =P23-P34 -> -3.8149355 | R36: =+P36+L36+H36+N36 -> -4.5897718
B37: EBTD per unit | C37: $/t | E37: =+E36/E9*1000 -> 53.539619 | F37: =+F36/F9*1000 -> -25.28463 | G37: =+G36/G9*1000 -> -42.502389 | H37: =+H36/H9*1000 -> 2.0299038 | J37: =+J36/J9*1000 -> 59.849255 | K37: =+K36/K9*1000 -> -166.88309 | L37: =+L36/L9*1000 -> 19.837665 | N37: =+N36/N9*1000 -> -97.935506 | P37: =+P36/P9*1000 -> -54.499078 | R37: =+R36/R9*1000 -> -10.928028
B38: Margin | C38: % | E38: =E37/E16*100 -> 9.3262562 | F38: =F37/F16*100 -> -4.6466444 | G38: =G37/G16*100 -> -8.006483 | H38: =H37/H16*100 -> 0.3676879 | J38: =J37/J16*100 -> 10.425354 | K38: =K37/K16*100 -> -31.505723 | L38: =L37/L16*100 -> 3.5033909 | N38: =N37/N16*100 -> -17.059733 | P38: =P37/P16*100 -> -9.4933878 | R38: =R37/R16*100 -> -1.9508115
B40: Depretiation | C40: M $ | E40: ='Fixed Cost'!D49 -> 0.5975 | F40: =+'Fixed Cost'!D57 -> 0.5975 | G40: =+'Fixed Cost'!D65 -> 1.195 | H40: =SUM(E40:G40) -> 2.39 | J40: =+'Fixed Cost'!E49 -> 1.26 | K40: =+'Fixed Cost'!E65 -> 1.26 | L40: =SUM(J40:K40) -> 2.52 | N40: =+'Fixed Cost'!F11 -> 1.24 | P40: =+'Fixed Cost'!G11 -> 0.13 | R40: =+P40+L40+H40+N40 -> 6.28
B41: FC per unit | C41: $/t | E41: =(+E40+E34)/E9*1000 -> 57.425 | F41: =(+F40+F34)/F9*1000 -> 114.85 | G41: =(+G40+G34)/G9*1000 -> 135.11765 | H41: =(H34+H40)*1000/H9 -> 97.744681 | J41: =(+J40+J34)/J9*1000 -> 62.428571 | K41: =(+K40+K34)/K9*1000 -> 291.33333 | L41: =(L34+L40)*1000/L9 -> 102.82353 | N41: =(+N40+N34)/N9*1000 -> 259 | P41: =(+P40+P34)/P9*1000 -> 144.71429 | R41: =(R34+R40)*1000/R9 -> 118.11905
B43: EBT | C43: M $ | E43: =+E36-E40 -> 4.7564619 | F43: =+F36-F40 -> -1.8617315 | G43: =+G36-G40 -> -4.807703 | H43: =SUM(E43:G43) -> -1.9129726 | J43: =+J36-J40 -> 2.9294479 | K43: =+K36-K40 -> -3.7632464 | L43: =SUM(I43:K43) -> -0.83379851 | N43: =+N36-N40 -> -4.1780652 | P43: =+P36-P40 -> -3.9449355 | R43: =+P43+L43+H43+N43 -> -10.869772
B44: EBT per unit | C44: $/t | E44: =+E43/E9*1000 -> 47.564619 | F44: =+F43/F9*1000 -> -37.23463 | G44: =+G43/G9*1000 -> -56.561212 | H44: =+H43/H9*1000 -> -8.140309 | J44: =+J43/J9*1000 -> 41.849255 | K44: =+K43/K9*1000 -> -250.88309 | L44: =+L43/L9*1000 -> -9.8093943 | N44: =+N43/N9*1000 -> -139.26884 | P44: =+P43/P9*1000 -> -56.356221 | R44: =+R43/R9*1000 -> -25.880409
B45: Margin | C45: % | E45: =+E44/E16*100 -> 8.2854498 | F45: =+F44/F16*100 -> -6.8427375 | G45: =+G44/G16*100 -> -10.654845 | H45: =+H44/H16*100 -> -1.4745 | J45: =+J44/J16*100 -> 7.2898703 | K45: =+K44/K16*100 -> -47.364014 | L45: =+L44/L16*100 -> -1.7323684 | N45: =+N44/N16*100 -> -24.259733 | P45: =+P44/P16*100 -> -9.8168901 | R45: =+R44/R16*100 -> -4.6200284
B47: VC + FC | C47: $/t | E47: =E19+E41 -> 526.50945 | F47: =F19+F41 -> 577.38278 | G47: =G19+G41 -> 577.99912 | H47: =H19+H41 -> 555.95749 | J47: =J19+J41 -> 532.22482 | K47: =K19+K41 -> 770.57445 | L47: =L19+L41 -> 574.28652 | N47: =N19+N41 -> 719.00958 | P47: =P19+P41 -> 630.43029 | R47: =R19+R41 -> 583.72565
B48: BE Quantity | C48: K-ton | E48: =(E34+E40)/(E16-E19)*1000 -> 54.695884 | F48: =(F34+F40)/(F16-F19)*1000 -> 70.360521 | G48: =(G34+G40)/(G16-G19)*1000 -> 130.55854 | H48: =(H34+H40)/(H16-H19)*1000 -> 244.72699 | J48: =(J34+J40)/(J16-J19)*1000 -> 41.907279 | K48: =(K34+K40)/(K16-K19)*1000 -> 86.620001 | L48: =(L34+L40)/(L16-L19)*1000 -> 92.214675 | N48: =(N34+N40)/(N16-N19)*1000 -> 68.119357 | P48: =(P34+P40)/(P16-P19)*1000 -> 114.64715 | R48: =(R34+R40)/(R16-R19)*1000 -> 524.57402
H50: =1+'Production Requirments'!H47 -> 9 | I50: / 12

Sheet P&L LE Monthly
B2: P & L Statement per month LE
B4: FX | C4: =+'Fixed Cost'!D15 -> 16.2 | E4: EZDK | J4: EFS | N4: ERM | P4: ESR | R4: Total
B5: Items | C5: Unit | E5: Rebar | F5: Wire Rod | G5: HRC | H5: Sub-Total | J5: Rebar | K5: HRC | L5: Sub-Total | N5: Rebar | P5: Rebar
B7: Local Sales | C7: Ktons | E7: =+'Market Share'!E6 -> 100 | F7: =+'Market Share'!F6 -> 40 | G7: =+'Market Share'!G6 -> 45 | H7: =SUM(E7:G7) -> 185 | J7: =+'Market Share'!E7 -> 70 | K7: =+'Market Share'!G7 -> 7.5 | L7: =SUM(J7:K7) -> 77.5 | N7: =+'Market Share'!E8 -> 30 | P7: =+'Market Share'!E9 -> 70 | R7: =+P7+L7+H7+N7 -> 362.5
B8: Export Sales | C8: Ktons | E8: =+'Market Share'!E19 -> 0 | F8: =+'Market Share'!F19 -> 10 | G8: =+'Market Share'!G19 -> 40 | H8: =SUM(E8:G8) -> 50 | J8: =+'Market Share'!E20 -> 0 | K8: =+'Market Share'!G20 -> 7.5 | L8: =SUM(J8:K8) -> 7.5 | N8: 0 | P8: 0 | R8: =+P8+L8+H8+N8 -> 57.5
B9: Total Sales Quantity | C9: Ktons | E9: =SUM(E7:E8) -> 100 | F9: =SUM(F7:F8) -> 50 | G9: =SUM(G7:G8) -> 85 | H9: =SUM(H7:H8) -> 235 | J9: =SUM(J7:J8) -> 70 | K9: =SUM(K7:K8) -> 15 | L9: =SUM(L7:L8) -> 85 | N9: =SUM(N7:N8) -> 30 | P9: =SUM(P7:P8) -> 70 | R9: =+P9+L9+H9+N9 -> 420
B11: Local Sales Value | C11: M LE | E11: =+E12*E7/1000 -> 930 | F11: =F12*F7/1000 -> 363 | G11: =G12*G7/1000 -> 400.5 | H11: =SUM(E11:G11) -> 1693.5 | J11: =J12*J7/1000 -> 651 | K11: =+K12*K7/1000 -> 66.75 | L11: =SUM(J11:K11) -> 717.75 | N11: =N12*N7/1000 -> 279 | P11: =+P12*P9/1000 -> 651 | R11: =+P11+L11+H11+N11 -> 3341.25
B12: Price per unit | C12: LE/t | E12: =+'Market Share'!E29 -> 9300 | F12: =+'Market Share'!F29 -> 9075 | G12: =+'Market Share'!G29 -> 8900 | H12: =+H11/H7*1000 -> 9154.0541 | J12: =+'Market Share'!E30 -> 9300 | K12: =+'Market Share'!G30 -> 8900 | L12: =+L11/L7*1000 -> 9261.2903 | N12: =+'Market Share'!E31 -> 9300 | P12: =+'Market Share'!E32 -> 9300 | R12: =+R11/R7*1000 -> 9217.2414
B13: Export Sales Value | C13: M LE | E13: =E14*E8/1000 -> 0 | F13: =F14*F8/1000 -> 77.76 | G13: =+G14*G8/1000 -> 330.48 | H13: =SUM(E13:G13) -> 408.24 | J13: 0 | K13: =+K14*K8/1000 -> 61.965 | L13: =SUM(J13:K13) -> 61.965 | N13: 0 | P13: 0 | R13: =+P13+L13+H13+N13 -> 470.205
B14: Price per unit | C14: LE/t | E14: =+'Market Share'!E34*C4 -> 7938 | F14: =+'Market Share'!F34*C4 -> 7776 | G14: =+'Market Share'!G34*C4 -> 8262 | H14: =+H13/H8*1000 -> 8164.8 | J14: 0 | K14: =+'Market Share'!G35*C4 -> 8262 | L14: 0 | N14: 0 | P14: 0 | R14: =+R13/R8*1000 -> 8177.4783
B15: Total Sales Value | C15: M LE | E15: =+E13+E11 -> 930 | F15: =+F13+F11 -> 440.76 | G15: =+G13+G11 -> 730.98 | H15: =SUM(E15:G15) -> 2101.74 | J15: =+J13+J11 -> 651 | K15: =+K13+K11 -> 128.715 | L15: =SUM(J15:K15) -> 779.715 | N15: =+N13+N11 -> 279 | P15: =+P13+P11 -> 651 | R15: =+P15+L15+H15+N15 -> 3811.455
B16: Average price per unit | C16: LE/t | E16: =+E15*1000/(E9) -> 9300 | F16: =F15/F9*1000 -> 8815.2 | G16: =+G15/G9*1000 -> 8599.7647 | H16: =+H15/H9*1000 -> 8943.5745 | J16: =+J15*1000/(J9) -> 9300 | K16: =+K15*1000/(K9) -> 8581 | L16: =+L15/L9*1000 -> 9173.1176 | N16: =+N15*1000/(N9) -> 9300 | P16: =P15/P9*1000 -> 9300 | R16: =+R15/R9*1000 -> 9074.8929
B18: Varible COGS | C18: M LE | E18: =(+E19*E9)/1000 -> 759.91682 | F18: =+F19*F9/1000 -> 374.65155 | G18: =+G19*G9/1000 -> 609.84779 | H18: =SUM(E18:G18) -> 1744.4162 | J18: =J19*J9/1000 -> 532.74894 | K18: =K19*K9/1000 -> 116.45559 | L18: =SUM(J18:K18) -> 649.20454 | N18: =N19*N9/1000 -> 223.56466 | P18: =P19*P9/1000 -> 550.80195 | R18: =+P18+L18+H18+N18 -> 3167.9873
B19: Cost per unit | C19: LE/t | E19: =+'EZDK Rebar'!E205*C4 -> 7599.1682 | F19: =+'EZDK Wire'!E86 -> 7493.031 | G19: =+'EZDK Flat'!E205*C4 -> 7174.6799 | H19: =+H18/H9*1000 -> 7423.0475 | J19: =+'EFS Rebar'!E205*C4 -> 7610.6992 | K19: ='EFS Flat'!E205*C4 -> 7763.7061 | L19: =+L18/L9*1000 -> 7637.7004 | N19: =+'ERM Rolling'!E86 -> 7452.1552 | P19: ='ESR Rebar'!E161*C4 -> 7868.5993 | R19: =+R18/R9*1000 -> 7542.8269
B21: Exporting expences | C21: LE/t | E21: 0 | F21: =+C4*0.2 -> 3.24 | G21: =+C4*0.8 -> 12.96 | H21: =SUM(E21:G21) -> 16.2 | J21: 0 | K21: =+C4*0.15 -> 2.43 | L21: =+K21 -> 2.43 | N21: 0 | P21: 0 | R21: =+P21+L21+H21+N21 -> 18.63
B23: Contribution Margin value | C23: M LE | E23: =E15-E18-E21 -> 170.08318 | F23: =F15-F18-F21 -> 62.86845 | G23: =G15-G18-G21 -> 108.17221 | H23: =SUM(E23:G23) -> 341.12384 | J23: =J15-J18-J21 -> 118.25106 | K23: =K15-K18-K21 -> 9.8294088 | L23: =SUM(I23:K23) -> 128.08046 | N23: =N15-N18-N21 -> 55.435344 | P23: =P15-P18-P21 -> 100.19805 | R23: =+P23+L23+H23+N23 -> 624.8377
B24: CM per unit | C24: LE/t | E24: =E23*1000/E9 -> 1700.8318 | F24: =F23*1000/F9 -> 1257.369 | G24: =G23*1000/G9 -> 1272.6142 | H24: =+H23/H9*1000 -> 1451.5908 | J24: =J23*1000/J9 -> 1689.3008 | K24: =K23*1000/K9 -> 655.29392 | L24: =+L23/L9*1000 -> 1506.829 | N24: =N23*1000/N9 -> 1847.8448 | P24: =P23*1000/P9 -> 1431.4007 | R24: =+R23/R9*1000 -> 1487.7088
B25: Margin | C25: % | E25: =E24/E16*100 -> 18.288514 | F25: =F24/F16*100 -> 14.263647 | G25: =G24/G16*100 -> 14.798245 | H25: =H24/H16*100 -> 16.230544 | J25: =J24/J16*100 -> 18.164525 | K25: =K24/K16*100 -> 7.6365682 | L25: =L24/L16*100 -> 16.426574 | N25: =N24/N16*100 -> 19.869299 | P25: =P24/P16*100 -> 15.391405 | R25: =R24/R16*100 -> 16.393679
B27: Intercompany Gains
B28: DRI | C28: M LE | N28: =0.17*C4 -> 2.754 | R28: =+N28 -> 2.754
B29: Billet | C29: M LE
B31: Manufacturing Fixed Cost | C31: M LE | E31: =+'Fixed Cost'!D46*C4 -> 40.2165 | F31: =+'Fixed Cost'!D54*C4 -> 40.2165 | G31: =+'Fixed Cost'!D62*C4 -> 80.433 | H31: =SUM(E31:G31) -> 160.866 | J31: =+'Fixed Cost'!E46*C4 -> 28.674 | K31: =+'Fixed Cost'!E62*C4 -> 28.674 | L31: =SUM(I31:K31) -> 57.348 | N31: =+'Fixed Cost'!F7*C4 -> 18.954 | P31: =+'Fixed Cost'!G46*C4 -> 39.69 | R31: =+P31+L31+H31+N31 -> 276.858
B32: SG&A | C32: M LE | E32: =+'Fixed Cost'!D47*C4 -> 14.823 | F32: =+'Fixed Cost'!D55*C4 -> 14.823 | G32: =+'Fixed Cost'!D63*C4 -> 29.646 | H32: =SUM(E32:G32) -> 59.292 | J32: =+'Fixed Cost'!E47*C4 -> 2.106 | K32: =+'Fixed Cost'!E63*C4 -> 2.106 | L32: =SUM(I32:K32) -> 4.212 | N32: =+'Fixed Cost'!F8*C4 -> 13.608 | P32: =+'Fixed Cost'!G47*C4 -> 38.556 | R32: =+P32+L32+H32+N32 -> 115.668
B33: Net Financing Cost | C33: M LE | E33: =+'Fixed Cost'!D48*C4 -> 28.3095 | F33: =+'Fixed Cost'!D56*C4 -> 28.3095 | G33: =+'Fixed Cost'!D64*C4 -> 56.619 | H33: =SUM(E33:G33) -> 113.238 | J33: =+'Fixed Cost'!E48*C4 -> 19.602 | K33: =+'Fixed Cost'!E64*C4 -> 19.602 | L33: =SUM(I33:K33) -> 39.204 | N33: =+'Fixed Cost'!F9*C4 -> 73.224 | P33: =+'Fixed Cost'!G48*C4 -> 83.754 | R33: =+P33+L33+H33+N33 -> 309.42
B34: Total Fixed Exp | C34: M LE | E34: =SUM(E31:E33) -> 83.349 | F34: =SUM(F31:F33) -> 83.349 | G34: =SUM(G31:G33) -> 166.698 | H34: =SUM(E34:G34) -> 333.396 | J34: =SUM(J31:J33) -> 50.382 | K34: =SUM(K31:K33) -> 50.382 | L34: =SUM(I34:K34) -> 100.764 | N34: =SUM(N31:N33) -> 105.786 | P34: =SUM(P31:P33) -> 162 | R34: =+P34+L34+H34+N34 -> 701.946
B36: Cash Earning before Tax & Dep | C36: M LE | E36: =E23-E34 -> 86.734183 | F36: =F23-F34 -> -20.48055 | G36: =G23-G34 -> -58.525789 | H36: =SUM(E36:G36) -> 7.7278436 | J36: =J23-J34 -> 67.869055 | K36: =K23-K34 -> -40.552591 | L36: =SUM(I36:K36) -> 27.316464 | N36: =N23+N28-N34 -> -47.596656 | P36: =P23-P34 -> -61.801954 | R36: =+P36+L36+H36+N36 -> -74.354302
B37: EBTD per unit | C37: LE/t | E37: =+E36/E9*1000 -> 867.34183 | F37: =+F36/F9*1000 -> -409.611 | G37: =+G36/G9*1000 -> -688.5387 | H37: =+H36/H9*1000 -> 32.884441 | J37: =+J36/J9*1000 -> 969.55793 | K37: =+K36/K9*1000 -> -2703.5061 | L37: =+L36/L9*1000 -> 321.37017 | N37: =+N36/N9*1000 -> -1586.5552 | P37: =+P36/P9*1000 -> -882.88506 | R37: =+R36/R9*1000 -> -177.03405
B38: Margin | C38: % | E38: =E37/E16*100 -> 9.3262562 | F38: =F37/F16*100 -> -4.6466444 | G38: =G37/G16*100 -> -8.006483 | H38: =H37/H16*100 -> 0.3676879 | J38: =J37/J16*100 -> 10.425354 | K38: =K37/K16*100 -> -31.505723 | L38: =L37/L16*100 -> 3.5033909 | N38: =N37/N16*100 -> -17.059733 | P38: =P37/P16*100 -> -9.4933878 | R38: =R37/R16*100 -> -1.9508115
B40: Depretiation | C40: M LE | E40: ='Fixed Cost'!D49*C4 -> 9.6795 | F40: =+'Fixed Cost'!D57*C4 -> 9.6795 | G40: =+'Fixed Cost'!D65*C4 -> 19.359 | H40: =SUM(E40:G40) -> 38.718 | J40: =+'Fixed Cost'!E49*C4 -> 20.412 | K40: =+'Fixed Cost'!E65*C4 -> 20.412 | L40: =SUM(J40:K40) -> 40.824 | N40: =+'Fixed Cost'!F11*C4 -> 20.088 | P40: =+'Fixed Cost'!G11*C4 -> 2.106 | R40: =+P40+L40+H40+N40 -> 101.736
B41: FC per unit | C41: LE/t | E41: =(+E40+E34)/E9*1000 -> 930.285 | F41: =(+F40+F34)/F9*1000 -> 1860.57 | G41: =(+G40+G34)/G9*1000 -> 2188.9059 | H41: =(H34+H40)*1000/H9 -> 1583.4638 | J41: =(+J40+J34)/J9*1000 -> 1011.3429 | K41: =(+K40+K34)/K9*1000 -> 4719.6 | L41: =(L34+L40)*1000/L9 -> 1665.7412 | N41: =(+N40+N34)/N9*1000 -> 4195.8 | P41: =(+P40+P34)/P9*1000 -> 2344.3714 | R41: =(R34+R40)*1000/R9 -> 1913.5286
B43: EBT | C43: M LE | E43: =+E36-E40 -> 77.054683 | F43: =+F36-F40 -> -30.16005 | G43: =+G36-G40 -> -77.884789 | H43: =SUM(E43:G43) -> -30.990156 | J43: =+J36-J40 -> 47.457055 | K43: =+K36-K40 -> -60.964591 | L43: =SUM(I43:K43) -> -13.507536 | N43: =+N36-N40 -> -67.684656 | P43: =+P36-P40 -> -63.907954 | R43: =+P43+L43+H43+N43 -> -176.0903
B44: EBT per unit | C44: LE/t | E44: =+E43/E9*1000 -> 770.54683 | F44: =+F43/F9*1000 -> -603.201 | G44: =+G43/G9*1000 -> -916.29164 | H44: =+H43/H9*1000 -> -131.87301 | J44: =+J43/J9*1000 -> 677.95793 | K44: =+K43/K9*1000 -> -4064.3061 | L44: =+L43/L9*1000 -> -158.91219 | N44: =+N43/N9*1000 -> -2256.1552 | P44: =+P43/P9*1000 -> -912.97078 | R44: =+R43/R9*1000 -> -419.26262
B45: Margin | C45: % | E45: =+E44/E16*100 -> 8.2854498 | F45: =+F44/F16*100 -> -6.8427375 | G45: =+G44/G16*100 -> -10.654845 | H45: =+H44/H16*100 -> -1.4745 | J45: =+J44/J16*100 -> 7.2898703 | K45: =+K44/K16*100 -> -47.364014 | L45: =+L44/L16*100 -> -1.7323684 | N45: =+N44/N16*100 -> -24.259733 | P45: =+P44/P16*100 -> -9.8168901 | R45: =+R44/R16*100 -> -4.6200284
B47: VC + FC | C47: LE/t | E47: =E19+E41 -> 8529.4532 | F47: =F19+F41 -> 9353.601 | G47: =G19+G41 -> 9363.5858 | H47: =H19+H41 -> 9006.5113 | J47: =J19+J41 -> 8622.0421 | K47: =K19+K41 -> 12483.306 | L47: =L19+L41 -> 9303.4416 | N47: =N19+N41 -> 11647.955 | P47: =P19+P41 -> 10212.971 | R47: =R19+R41 -> 9456.3555
B48: BE Quantity | C48: K-ton | E48: =(E34+E40)/(E16-E19)*1000 -> 54.695884 | F48: =(F34+F40)/(F16-F19)*1000 -> 70.360521 | G48: =(G34+G40)/(G16-G19)*1000 -> 130.55854 | H48: =(H34+H40)/(H16-H19)*1000 -> 244.72699 | J48: =(J34+J40)/(J16-J19)*1000 -> 41.907279 | K48: =(K34+K40)/(K16-K19)*1000 -> 86.620001 | L48: =(L34+L40)/(L16-L19)*1000 -> 92.214675 | N48: =(N34+N40)/(N16-N19)*1000 -> 68.119357 | P48: =(P34+P40)/(P16-P19)*1000 -> 114.64715 | R48: =(R34+R40)/(R16-R19)*1000 -> 524.57402
P49: =P47*840000 -> 8.5788955e+09
H50: =+'P&L $ Monthly'!H50+1 -> 10 | I50: / 12 | P50: =P49/3 -> 2.8596318e+09

Sheet P&L $ Annual
B2: P & L Statement per Annual USD
E4: EZDK | J4: EFS | N4: ERM | P4: ESR | R4: Total
B5: Items | C5: Unit | E5: Rebar | F5: Wire Rod | G5: HRC | H5: Sub-Total | J5: Rebar | K5: HRC | L5: Sub-Total | N5: Rebar | P5: Rebar
B7: Local Sales | C7: Ktons | E7: =+'Market Share'!E6*12 -> 1200 | F7: =+'Market Share'!F6*12 -> 480 | G7: =+'Market Share'!G6*12 -> 540 | H7: =SUM(E7:G7) -> 2220 | J7: =+'Market Share'!E7*12 -> 840 | K7: =+'Market Share'!G7*12 -> 90 | L7: =SUM(J7:K7) -> 930 | N7: =+'Market Share'!E8*12 -> 360 | P7: =+'Market Share'!E9*12 -> 840 | R7: =+P7+L7+H7+N7 -> 4350
B8: Export Sales | C8: Ktons | E8: =+'Market Share'!E19*12 -> 0 | F8: =+'Market Share'!F19*12 -> 120 | G8: =+'Market Share'!G19*12 -> 480 | H8: =SUM(E8:G8) -> 600 | J8: =+'Market Share'!E20 -> 0 | K8: =+'Market Share'!G20*12 -> 90 | L8: =SUM(J8:K8) -> 90 | N8: 0 | P8: 0 | R8: =+P8+L8+H8+N8 -> 690
B9: Total Sales Quantity | C9: Ktons | E9: =SUM(E7:E8) -> 1200 | F9: =SUM(F7:F8) -> 600 | G9: =SUM(G7:G8) -> 1020 | H9: =SUM(H7:H8) -> 2820 | J9: =SUM(J7:J8) -> 840 | K9: =SUM(K7:K8) -> 180 | L9: =SUM(L7:L8) -> 1020 | N9: =SUM(N7:N8) -> 360 | P9: =SUM(P7:P8) -> 840 | R9: =+P9+L9+H9+N9 -> 5040
